Workbook
Name _TWM3: [1]Djabal_materials!$M$277
Name a: #REF!
Name a: #REF!
Name aa: [0]!See_all_items
Name aa: [2]!See_all_items
Name aq: #REF!
Name aq: #REF!
Name atot: #REF!
Name atot: #REF!
Name atuot: #REF!
Name atuot: #REF!
Name az: #REF!
Name az: #REF!
Name b: #REF!
Name b: #REF!
Name BASE: #REF!
Name BASE: #REF!
Name Bom: #REF!
Name Bom: #REF!
Name btot: #REF!
Name btot: #REF!
Name budget: '[3]Budget Line Item'!#REF!
Name budget: '[3]Budget Line Item'!#REF!
Name budtot: #REF!
Name budtot: #REF!
Name budtotpart: '[4]5.1 Budget partners'!$J$86
Name ca: #REF!
Name ca: #REF!
Name cami: #REF!
Name cami: #REF!
Name cd: #REF!
Name cd: #REF!
Name Col_Headings: #REF!
Name Col_Headings: #REF!
Name ctot: #REF!
Name ctot: #REF!
Name d: #REF!
Name d: #REF!
Name dash: #REF!
Name datalookuparea: '[5]Scoring Base input'!$A$7:$AV$99
Name ddddddddddd: #REF!
Name ddddddddddd: #REF!
Name dtot: #REF!
Name dtot: #REF!
Name dz: #REF!
Name dz: #REF!
Name es: #REF!
Name es: #REF!
Name FCT_DETAIL1: '[6]1 Parameters'!$AX$6:$AX$115
Name FCT_DETAIL2: '[6]1 Parameters'!$AX$6:$AY$115
Name FCT_NOMCATCOMPTA: '[6]1 Parameters'!$AR$6:$AR$28
Name ff: #REF!
Name ftot: #REF!
Name ftot: #REF!
Name ganttSymbols: [7]Legend!$D$3:$D$6
Name ganttSymbols: [8]Legend!$D$3:$D$6
Name gtot: #REF!
Name gtot: #REF!
Name htot: #REF!
Name htot: #REF!

Sheet Instructions
B1: Guidelines For Completing the Project tracking tool
B3: KEY
C4: Fill in for each monitoring
C5: Fill in AT THE START OF THE PROJECT
C6: Information available in the project proposal or Formulas - DO NOT DELETE/MODIFY !
B8: WHO | C8: The initiation process and preparation of the sheet should start with MEAL staff, then Coordinators take over and fill all required information and planning. Fully participatory process between MEAL and program teams.
B10: WHEN | C10: Monthly for The project workplan, output indicator and beneficiaries database. For the remaining spreadsheets the appropriate frequency is quarterly for long-term projects and bi-monthly or monthly for short projects.
B12: WHY | C12: 1. To enable a systematic follow up of the project's progress towards expected results (activity, indicators, beneficiaries and assumptions) by the coordinators, CEO and M&E 2. To serve as a support for regular project meetings 3. To facilitate project reporting 4. To facilitate the Management team the monitoring of project's progress and challenges at to provide a quick overview which allows for faster feedback
B13: planning sheets | C13: sheets that should be filled once at the beginning of the project
B15: Monitoring sheets | C15: sheets that should be updated regularly after preparation at the planning stage

Sheet Poject Info. Sheet
B1: Project Tracking Tool-NAWA association
B2: Project Code
B3: Project Title
B4: Overall/Principal Objective
B5: Brief Summary about the intervention
B6: Start date | F6: End date
B7: Project Manager/coordinator | F7: Duration
B8: Total Budget | F8: Currency
B9: Donor Share | F9: Currency
B10: Nawa Share | F10: Currency
B11: total Direct Beneficiaries planned | C11: 7595
B12: Modification request or Amendement | C12: FALSE | F12: Date of MR | H12: If Yes, please explain.
B13: Donor
B14: Sectors | C14: Cultural | H14: FALSE
C15: Artistic | H15: FALSE
C16: Educational | H16: FALSE
C17: Psychosocial Support (Mental Health) | G17: FALSE | H17: TRUE
B18: Implementing partners | C18: INGO | G18: FALSE
C19: NGO | G19: FALSE
C20: Local Government (Ministries) MoEHE | G20: FALSE
C21: CBOs | G21: FALSE
C22: UN agencies | G22: FALSE
B23: Geographical coverage | C23: Deir Al Balah
B25: Target Group (s) | C25: Children- School age | G25: FALSE
C26: children pre school | G26: FALSE
C27: Parents | G27: FALSE
C28: Local Educators | G28: FALSE
C29: Nawa Educators | G29: FALSE
B30: Donor Reporting Requirements | C30: Report # | E30: Reporting period | G30: submission date | H30: Responsible
E31: From | F31: To
C32: Donor report 1
C33: Donor report 2
C34: Donor report 3
C35: Donor report 4
C36: Donor report 5
C37: Donor report 6
C38: Donor report 7
C39: Donor report 8
C40: Donor report 9
C41: Donor report 10

Sheet Log frame
A1: Title of the Project
C2: Objectively Verifiable Indicators | D2: Target Value | E2: Sources of Verification | F2: Risks and Assumptions
A3: Overall Impact
A5: Outcome (1)
A7: Output 1.1
A8: Activities 1.1
A17: Output 1.2
A18: Outcome (2)
A20: Output 2.1
A21: Output 2.2
A22: Activities 2.2
A23: Outcome (3)
A27: Output 3.1
A29: Activities 3.1
... A35: Activities 2.2

Sheet Overview Dashboard
C1: Project Start | D1: ='Poject Info. Sheet'!C6 -> 0 | E1: Overview Dashboard report | J1: Actual progress | M1: Remaining | O1: this is automatic generated Dash board please don't change focmulas
C2: Project End | D2: ='Poject Info. Sheet'!H6 -> 0 | J2: Time spent (%) | L2: =DAYS360(D1,A5)/DAYS360(D1,D2) -> #DIV/0! | M2: =100%-L2 -> #DIV/0!
C3: Budget spent | D3: fill it | J3: Implementation(%) | L3: ='Project Work plan'!$C$118 -> #DIV/0! | M3: =100%-L3 -> #DIV/0!
C4: Duration | D4: fill it | J4: Budget use (%) | L4: =D3/'Poject Info. Sheet'!C9 -> #VALUE! | M4: =38% -> 0.38
A5: =TODAY() -> 44184
A6: Direct Beneficiaries- Overview
B17: Profile | G17: Activity | K17: Activity Progress | O17: Results' Progress
K18: ='Project Work plan'!A108 -> Activity 1.1 | L18: ='Project Work plan'!C108 -> #DIV/0! | O18: Result 1 | P18: =AVERAGE('Project Work plan'!C108:C110) -> #DIV/0!
C19: ='Beneficiaries Breakdown'!D7 -> 125 | G19: ='Beneficiaries Breakdown'!C35 -> 8 | K19: ='Project Work plan'!A109 -> Activity 1.2 | L19: ='Project Work plan'!C109 -> #DIV/0!
K20: ='Project Work plan'!A110 -> Activity 1.3 | L20: ='Project Work plan'!C110 -> #DIV/0! | O20: Result 2 | P20: =AVERAGE('Project Work plan'!C111:C115) -> #DIV/0!
G21: ='Beneficiaries Breakdown'!D35 -> 130 | K21: ='Project Work plan'!A111 -> Activity 2.1 | L21: ='Project Work plan'!C111 -> #DIV/0!
C22: ='Beneficiaries Breakdown'!E7 -> 425 | K22: ='Project Work plan'!A112 -> Activity 2.2 | L22: ='Project Work plan'!C112 -> #DIV/0! | O22: Result 3 | P22: =AVERAGE('Project Work plan'!C116:C117) -> #DIV/0!
G23: ='Beneficiaries Breakdown'!E35 -> 398 | K23: ='Project Work plan'!A113 -> Activity 2.3 | L23: ='Project Work plan'!C113 -> #DIV/0!
K24: ='Project Work plan'!A114 -> Activity 2.4 | L24: ='Project Work plan'!C114 -> #DIV/0!
C25: =SUM('Beneficiaries Breakdown'!F7:G7) -> 8 | G25: =SUM('Beneficiaries Breakdown'!F35:G35) -> 63 | K25: ='Project Work plan'!A115 -> Activity 2.5 | L25: ='Project Work plan'!C115 -> #DIV/0!
K26: ='Project Work plan'!A116 -> Activity 3.1 | L26: ='Project Work plan'!C116 -> #DIV/0!
K27: ='Project Work plan'!A117 -> Activity 3.2 | L27: ='Project Work plan'!C117 -> #DIV/0!
A29: Direct Beneficiaries -per Quarter
C30: Quarter 1 | J30: Quarter 2
C47: Quarter 3 | J47: Quarter 4
A64: Direct beneficiaries- per Activity Quarter 1
A113: Direct beneficiaries- per Activity Quarter 2

Sheet Indicator Profile
A1: Results' Level | B1: Intervention Logic | C1: Indicators | D1: Definition | E1: Calculation method | F1: Disaggregation | G1: Baseline Requirements | H1: Data collection Frequency | I1: Reporting Frequency | J1: Means of Verification | K1: Data source | L1: Data collection Method | M1: Sampling | N1: MIS | O1: Lessons Learnt (optional) | R1: Data collection | S1: Data entry | T1: Data verification | U1: Data analysis | V1: Data archiving
A2: Overall Impact
A4: outcomes
A12: Outputs

Sheet Project Work plan
A1: Detailed Implementation Plan | H1: Period of Action (annual)
A2: Results | B2: Activities | C2: Target | E2: Sub Activity (in case) | F2: Status | G2: Responsible Person | H2: 43922 | L2: 43952 | P2: 43983 | T2: 44013 | X2: 44044 | AB2: 44075 | AF2: 44105 | AJ2: 44136 | AN2: 44166 | AR2: 44197 | AV2: 44228 | AZ2: 44256 | BD2: planned/actual | BE2: Progress | BF2: 43925 | BG2: 43955 | BH2: 43986 | BI2: 44016 | BJ2: 44047 | BK2: 44078 | BL2: 44108 | BM2: 44139 | BN2: 44169 | BO2: 44200 | BP2: 44231 | BQ2: 44259
H3: W1 | I3: W2 | J3: W3 | K3: W4 | L3: W1 | M3: W2 | N3: W3 | O3: W4 | P3: W1 | Q3: W2 | R3: W3 | S3: W4 | T3: W1 | U3: W2 | V3: W3 | W3: W4 | X3: W1 | Y3: W2 | Z3: W3 | AA3: W4 | AB3: W1 | AC3: W2 | AD3: W3 | AE3: W4 | AF3: W1 | AG3: W2 | AH3: W3 | AI3: W4 | AJ3: W1 | AK3: W2 | AL3: W3 | AM3: W4 | AN3: W1 | AO3: W2 | AP3: W3 | AQ3: W4 | AR3: W1 | AS3: W2 | AT3: W3 | AU3: W4 | AV3: W1 | AW3: W2 | AX3: W3 | AY3: W4 | AZ3: W1 | BA3: W2 | BB3: W3 | BC3: W4 | BF3: Narrative/Comments/Explanations | BG3: Narrative/Comments/Explanations | BH3: Narrative/Comments/Explanations | BI3: Narrative/Comments/Explanations | BJ3: Narrative/Comments/Explanations | BK3: Narrative/Comments/Explanations | BL3: Narrative/Comments/Explanations | BM3: Narrative/Comments/Explanations | BN3: Narrative/Comments/Explanations | BO3: Narrative/Comments/Explanations | BP3: Narrative/Comments/Explanations | BQ3: Narrative/Comments/Explanations
C4: unit | D4: value
F5: Planned | BC5: 1 | BD5: =SUM(H5:BC5) -> 1 | BE5: =BD6/BD5 -> 0
F6: Actual | BD6: =SUM(H6:BC6) -> 0
F7: Planned | BD7: =SUM(H7:BC7) -> 0 | BE7: =BD8/BD7 -> #DIV/0!
F8: Actual | BD8: =SUM(H8:BC8) -> 0
F9: Planned | BD9: =SUM(H9:BC9) -> 0 | BE9: =BD10/BD9 -> #DIV/0!
F10: Actual | BD10: =SUM(H10:BC10) -> 0
F11: Planned | BD11: =SUM(H11:BC11) -> 0 | BE11: =BD12/BD11 -> #DIV/0!
F12: Actual | BD12: =SUM(H12:BC12) -> 0
F13: Planned | BD13: =SUM(H13:BC13) -> 0 | BE13: =BD14/BD13 -> #DIV/0!
F14: Actual | BD14: =SUM(H14:BC14) -> 0
F15: Planned | BD15: =SUM(H15:BC15) -> 0 | BE15: =BD16/BD15 -> #DIV/0!
F16: Actual | BD16: =SUM(H16:BC16) -> 0
F17: Planned | BD17: =SUM(H17:BC17) -> 0 | BE17: =BD18/BD17 -> #DIV/0!
F18: Actual | BD18: =SUM(H18:BC18) -> 0
F19: Planned | BD19: =SUM(H19:BC19) -> 0 | BE19: =BD20/BD19 -> #DIV/0!
F20: Actual | BD20: =SUM(H20:BC20) -> 0
F21: Planned | BD21: =SUM(H21:BC21) -> 0 | BE21: =BD22/BD21 -> #DIV/0!
F22: Actual | BD22: =SUM(H22:BC22) -> 0
F23: Planned | BD23: =SUM(H23:BC23) -> 0 | BE23: =BD24/BD23 -> #DIV/0!
F24: Actual | BD24: =SUM(H24:BC24) -> 0
F25: Planned | BD25: =SUM(H25:BC25) -> 0 | BE25: =BD26/BD25 -> #DIV/0!
F26: Actual | BD26: =SUM(H26:BC26) -> 0
F27: Planned | BD27: =SUM(H27:BC27) -> 0 | BE27: =BD28/BD27 -> #DIV/0!
F28: Actual | BD28: =SUM(H28:BC28) -> 0
F29: Planned | BD29: =SUM(H29:BC29) -> 0 | BE29: =BD30/BD29 -> #DIV/0!
F30: Actual | BD30: =SUM(H30:BC30) -> 0
F31: Planned | BD31: =SUM(H31:BC31) -> 0 | BE31: =BD32/BD31 -> #DIV/0!
F32: Actual | BD32: =SUM(H32:BC32) -> 0
F33: Planned | BD33: =SUM(H33:BC33) -> 0 | BE33: =BD34/BD33 -> #DIV/0!
F34: Actual | BD34: =SUM(H34:BC34) -> 0
F35: Planned | BD35: =SUM(H35:BC35) -> 0 | BE35: =BD36/BD35 -> #DIV/0!
F36: Actual | BD36: =SUM(H36:BC36) -> 0
F37: Planned | BD37: =SUM(H37:BC37) -> 0 | BE37: =BD38/BD37 -> #DIV/0!
F38: Actual | BD38: =SUM(H38:BC38) -> 0
F39: Planned | BD39: =SUM(H39:BC39) -> 0 | BE39: =BD40/BD39 -> #DIV/0!
F40: Actual | BD40: =SUM(H40:BC40) -> 0
...

Sheet ورقة1

Sheet Project Tracking Table -PTT
A1: Level | B1: Result | C1: Indicators | D1: Start Date | E1: End date | F1: Baseline | J1: Baseline | K1: Target | O1: Target | P1: Actual | T1: Total | U1: Achievement | Y1: Total achieved | Z1: Narrative/Comment
F2: M | G2: FM | H2: CWD M | I2: CWD FM | K2: M | L2: FM | M2: CWD M | N2: CWD FM | P2: M | Q2: FM | R2: CWD M | S2: CWD FM | U2: M | V2: FM | W2: CWD M | X2: CWD FM
A3: Overall Objective | J3: =AVERAGE(F3:I3) -> #DIV/0! | O3: =AVERAGE(K3:N3) -> #DIV/0! | P3: ='Outcome indicators'!AI4 -> #DIV/0! | Q3: ='Outcome indicators'!AJ4 -> #DIV/0! | R3: ='Outcome indicators'!AK4 -> #DIV/0! | S3: ='Outcome indicators'!AL4 -> #DIV/0! | T3: =AVERAGE(P3:Q3) -> #DIV/0! | U3: =P3/K3 -> #DIV/0! | V3: =Q3/L3 -> #DIV/0! | W3: =R3/M3 -> #DIV/0! | X3: =S3/N3 -> #DIV/0! | Y3: =T3/O3 -> #DIV/0!
J4: =AVERAGE(F4:I4) -> #DIV/0! | O4: =AVERAGE(K4:N4) -> #DIV/0! | P4: ='Outcome indicators'!AI5 -> #DIV/0! | Q4: ='Outcome indicators'!AJ5 -> #DIV/0! | R4: ='Outcome indicators'!AK5 -> #DIV/0! | S4: ='Outcome indicators'!AL5 -> #DIV/0! | T4: =AVERAGE(P4:Q4) -> #DIV/0! | U4: =P4/K4 -> #DIV/0! | V4: =Q4/L4 -> #DIV/0! | W4: =R4/M4 -> #DIV/0! | X4: =S4/N4 -> #DIV/0! | Y4: =T4/O4 -> #DIV/0!
A5: # of direct BNFS | J5: =SUM(F5:I5) -> 0 | K5: =SUM(K13:K14,K16,K21,K22:K23) -> 0 | L5: =SUM(L13:L14,L16,L21,L22:L23) -> 0 | M5: =SUM(M13:M14,M16,M21,M22:M23) -> 0 | N5: =SUM(N13:N14,N16,N21,N22:N23) -> 0 | O5: =SUM(O13:O14,O16,O21,O22:O23) -> 0 | P5: =SUM(P13:P14,P16,P21,P22:P23) -> 0 | Q5: =SUM(Q13:Q14,Q16,Q21,Q22:Q23) -> 0 | R5: =SUM(R13:R14,R16,R21,R22:R23) -> 0 | S5: =SUM(S13:S14,S16,S21,S22:S23) -> 0 | T5: =SUM(P5:S5) -> 0 | U5: =P5/K5 -> #DIV/0! | V5: =Q5/L5 -> #DIV/0! | W5: =R5/M5 -> #DIV/0! | X5: =S5/N5 -> #DIV/0! | Y5: =T5/O5 -> #DIV/0!
A6: Outcomes | J6: =SUM(F6:I6) -> 0 | P6: ='Outcome indicators'!AI6 -> 0 | U6: =P6/K6 -> #DIV/0!
J7: =AVERAGE(F7:I7) -> #DIV/0! | O7: =AVERAGE(K7:N7) -> #DIV/0! | P7: ='Outcome indicators'!AI7 -> #DIV/0! | Q7: ='Outcome indicators'!AJ7 -> #DIV/0! | R7: ='Outcome indicators'!AK7 -> #DIV/0! | S7: ='Outcome indicators'!AL7 -> #DIV/0! | T7: =AVERAGE(P7:Q7) -> #DIV/0! | U7: =P7/K7 -> #DIV/0! | V7: =Q7/L7 -> #DIV/0! | W7: =R7/M7 -> #DIV/0! | X7: =S7/N7 -> #DIV/0! | Y7: =T7/O7 -> #DIV/0!
J8: =AVERAGE(F8:I8) -> #DIV/0! | O8: =AVERAGE(K8:N8) -> #DIV/0! | P8: ='Outcome indicators'!AI8 -> #DIV/0! | Q8: ='Outcome indicators'!AJ8 -> #DIV/0! | R8: ='Outcome indicators'!AK8 -> #DIV/0! | S8: ='Outcome indicators'!AL8 -> #DIV/0! | T8: =AVERAGE(P8:Q8) -> #DIV/0! | U8: =P8/K8 -> #DIV/0! | V8: =Q8/L8 -> #DIV/0! | W8: =R8/M8 -> #DIV/0! | X8: =S8/N8 -> #DIV/0! | Y8: =T8/O8 -> #DIV/0!
J9: =AVERAGE(F9:I9) -> #DIV/0! | O9: =AVERAGE(K9:N9) -> #DIV/0! | P9: ='Outcome indicators'!AI9 -> #DIV/0! | Q9: ='Outcome indicators'!AJ9 -> #DIV/0! | R9: ='Outcome indicators'!AK9 -> #DIV/0! | S9: ='Outcome indicators'!AL9 -> #DIV/0! | T9: =AVERAGE(P9:Q9) -> #DIV/0! | U9: =P9/K9 -> #DIV/0! | V9: =Q9/L9 -> #DIV/0! | W9: =R9/M9 -> #DIV/0! | X9: =S9/N9 -> #DIV/0! | Y9: =T9/O9 -> #DIV/0!
J10: =AVERAGE(F10:I10) -> #DIV/0! | O10: =AVERAGE(K10:N10) -> #DIV/0! | P10: ='Outcome indicators'!AI10 -> #DIV/0! | Q10: ='Outcome indicators'!AJ10 -> #DIV/0! | R10: ='Outcome indicators'!AK10 -> #DIV/0! | S10: ='Outcome indicators'!AL10 -> #DIV/0! | T10: =AVERAGE(P10:Q10) -> #DIV/0! | U10: =P10/K10 -> #DIV/0! | V10: =Q10/L10 -> #DIV/0! | W10: =R10/M10 -> #DIV/0! | X10: =S10/N10 -> #DIV/0! | Y10: =T10/O10 -> #DIV/0!
J11: =AVERAGE(F11:I11) -> #DIV/0! | O11: =AVERAGE(K11:N11) -> #DIV/0! | P11: ='Outcome indicators'!AI11 -> #DIV/0! | Q11: ='Outcome indicators'!AJ11 -> #DIV/0! | R11: ='Outcome indicators'!AK11 -> #DIV/0! | S11: ='Outcome indicators'!AL11 -> #DIV/0! | T11: =AVERAGE(P11:Q11) -> #DIV/0! | U11: =P11/K11 -> #DIV/0! | V11: =Q11/L11 -> #DIV/0! | W11: =R11/M11 -> #DIV/0! | X11: =S11/N11 -> #DIV/0! | Y11: =T11/O11 -> #DIV/0!
J12: =AVERAGE(F12:I12) -> #DIV/0! | O12: =AVERAGE(K12:N12) -> #DIV/0! | P12: ='Outcome indicators'!AI12 -> #DIV/0! | Q12: ='Outcome indicators'!AJ12 -> #DIV/0! | R12: ='Outcome indicators'!AK12 -> #DIV/0! | S12: ='Outcome indicators'!AL12 -> #DIV/0! | T12: =AVERAGE(P12:Q12) -> #DIV/0! | U12: =P12/K12 -> #DIV/0! | V12: =Q12/L12 -> #DIV/0! | W12: =R12/M12 -> #DIV/0! | X12: =S12/N12 -> #DIV/0! | Y12: =T12/O12 -> #DIV/0!
A13: Outputs | J13: =SUM(F13:I13) -> 0 | O13: =SUM(K13:N13) -> 0 | P13: ='Output indicators'!AZ4 -> 0 | Q13: ='Output indicators'!BA4 -> 0 | R13: ='Output indicators'!BB4 -> 0 | S13: ='Output indicators'!BC4 -> 0 | T13: =SUM(P13:S13) -> 0 | U13: =P13/K13 -> #DIV/0! | V13: =Q13/L13 -> #DIV/0! | W13: =R13/M13 -> #DIV/0! | X13: =S13/N13 -> #DIV/0! | Y13: =T13/O13 -> #DIV/0!
J14: =SUM(F14:I14) -> 0 | O14: =SUM(K14:N14) -> 0 | P14: ='Output indicators'!AZ5 -> 0 | Q14: ='Output indicators'!BA5 -> 0 | R14: ='Output indicators'!BB5 -> 0 | S14: ='Output indicators'!BC5 -> 0 | T14: =SUM(P14:S14) -> 0 | U14: =P14/K14 -> #DIV/0! | V14: =Q14/L14 -> #DIV/0! | W14: =R14/M14 -> #DIV/0! | X14: =S14/N14 -> #DIV/0! | Y14: =T14/O14 -> #DIV/0!
P15: ='Output indicators'!D6 -> 0 | U15: =P15/K15 -> #DIV/0!
J16: =SUM(F16:I16) -> 0 | O16: =SUM(K16:N16) -> 0 | P16: ='Output indicators'!AZ7 -> 0 | Q16: ='Output indicators'!BA7 -> 0 | R16: ='Output indicators'!BB7 -> 0 | S16: ='Output indicators'!BC7 -> 0 | T16: =SUM(P16:Q16) -> 0 | U16: =P16/K16 -> #DIV/0! | V16: =Q16/L16 -> #DIV/0! | W16: =R16/M16 -> #DIV/0! | X16: =S16/N16 -> #DIV/0! | Y16: =T16/O16 -> #DIV/0!
P17: ='Output indicators'!AZ8 -> 0 | U17: =P17/K17 -> #DIV/0!
P18: ='Output indicators'!AZ9 -> 0 | U18: =P18/K18 -> #DIV/0!
P19: ='Output indicators'!AZ10 -> 0 | U19: =P19/K19 -> #DIV/0!
P20: ='Output indicators'!AZ11 -> 0 | U20: =P20/K20 -> #DIV/0!
J21: =SUM(F21:I21) -> 0 | O21: =SUM(K21:N21) -> 0 | P21: ='Output indicators'!AZ12 -> 0 | Q21: ='Output indicators'!BA12 -> 0 | R21: ='Output indicators'!BB12 -> 0 | S21: ='Output indicators'!BC12 -> 0 | T21: =SUM(P21:Q21) -> 0 | U21: =P21/K21 -> #DIV/0! | V21: =Q21/L21 -> #DIV/0! | W21: =R21/M21 -> #DIV/0! | X21: =S21/N21 -> #DIV/0! | Y21: =T21/O21 -> #DIV/0!
J22: =SUM(F22:I22) -> 0 | O22: =SUM(K22:N22) -> 0 | P22: ='Output indicators'!AZ13 -> 0 | Q22: ='Output indicators'!BA13 -> 0 | R22: ='Output indicators'!BB13 -> 0 | S22: ='Output indicators'!BC13 -> 0 | T22: =SUM(P22:Q22) -> 0 | U22: =P22/K22 -> #DIV/0! | V22: =Q22/L22 -> #DIV/0! | W22: =R22/M22 -> #DIV/0! | X22: =S22/N22 -> #DIV/0! | Y22: =T22/O22 -> #DIV/0!
J23: =SUM(F23:I23) -> 0 | O23: =SUM(K23:N23) -> 0 | P23: ='Output indicators'!AZ14 -> 0 | Q23: ='Output indicators'!BA14 -> 0 | R23: ='Output indicators'!BB14 -> 0 | S23: ='Output indicators'!BC14 -> 0 | T23: =SUM(P23:Q23) -> 0 | U23: =P23/K23 -> #DIV/0! | V23: =Q23/L23 -> #DIV/0! | W23: =R23/M23 -> #DIV/0! | X23: =S23/N23 -> #DIV/0! | Y23: =T23/O23 -> #DIV/0!
P24: ='Output indicators'!AZ15 -> 0 | U24: =P24/K24 -> #DIV/0!
P25: ='Output indicators'!AZ16 -> 0 | U25: =P25/K25 -> #DIV/0!

Sheet Output indicators
A1: # | B1: outputs | C1: Indicator | D1: Q1 | P1: Q2 | AB1: Q3 | AN1: Q4 | AZ1: Total Year 1
D2: 43922 | H2: 43952 | L2: 43983 | P2: 44013 | T2: 44044 | X2: 44075 | AB2: 44105 | AF2: 44136 | AJ2: 44166 | AN2: 44197 | AR2: 44228 | AV2: 44256
D3: M | E3: FM | F3: CWD M | G3: CWD FM | H3: M | I3: FM | J3: CWD M | K3: CWD FM | L3: M | M3: FM | N3: CWD M | O3: CWD FM | P3: M | Q3: FM | R3: CWD M | S3: CWD FM | T3: M | U3: FM | V3: CWD M | W3: CWD FM | X3: M | Y3: FM | Z3: CWD M | AA3: CWD FM | AB3: M | AC3: FM | AD3: CWD M | AE3: CWD FM | AF3: M | AG3: FM | AH3: CWD M | AI3: CWD FM | AJ3: M | AK3: FM | AL3: CWD M | AM3: CWD FM | AN3: M | AO3: FM | AP3: CWD M | AQ3: CWD FM | AR3: M | AS3: FM | AT3: CWD M | AU3: CWD FM | AV3: M | AW3: FM | AX3: CWD M | AY3: CWD FM | AZ3: M | BA3: FM | BB3: CWD M | BC3: CWD FM
A4: output 1 | AZ4: =SUM(D4,H4,L4,P4,T4,X4,AB4,AF4,AJ4,AN4,AR4,AV4) -> 0 | BA4: =SUM(E4,I4,M4,Q4,U4,Y4,AC4,AG4,AK4,AO4,AS4,AW4) -> 0 | BB4: =SUM(F4,J4,N4,R4,V4,Z4,AD4,AH4,AL4,AP4,AT4,AX4) -> 0 | BC4: =SUM(G4,K4,O4,S4,W4,AA4,AE4,AI4,AM4,AQ4,AU4,AY4) -> 0
AZ5: =SUM(D5,H5,L5,P5,T5,X5,AB5,AF5,AJ5,AN5,AR5,AV5) -> 0 | BA5: =SUM(E5,I5,M5,Q5,U5,Y5,AC5,AG5,AK5,AO5,AS5,AW5) -> 0 | BB5: =SUM(F5,J5,N5,R5,V5,Z5,AD5,AH5,AL5,AP5,AT5,AX5) -> 0 | BC5: =SUM(G5,K5,O5,S5,W5,AA5,AE5,AI5,AM5,AQ5,AU5,AY5) -> 0
AZ6: =SUM(D6,H6,L6,P6,T6,X6,AB6,AF6,AJ6,AN6,AR6,AV6) -> 0 | BA6: =SUM(E6,I6,M6,Q6,U6,Y6,AC6,AG6,AK6,AO6,AS6,AW6) -> 0 | BB6: =SUM(F6,J6,N6,R6,V6,Z6,AD6,AH6,AL6,AP6,AT6,AX6) -> 0 | BC6: =SUM(G6,K6,O6,S6,W6,AA6,AE6,AI6,AM6,AQ6,AU6,AY6) -> 0
A7: output 2 | AZ7: =SUM(D7,H7,L7,P7,T7,X7,AB7,AF7,AJ7,AN7,AR7,AV7) -> 0 | BA7: =SUM(E7,I7,M7,Q7,U7,Y7,AC7,AG7,AK7,AO7,AS7,AW7) -> 0 | BB7: =SUM(F7,J7,N7,R7,V7,Z7,AD7,AH7,AL7,AP7,AT7,AX7) -> 0 | BC7: =SUM(G7,K7,O7,S7,W7,AA7,AE7,AI7,AM7,AQ7,AU7,AY7) -> 0
AZ8: =SUM(D8,H8,L8,P8,T8,X8,AB8,AF8,AJ8,AN8,AR8,AV8) -> 0 | BA8: =SUM(E8,I8,M8,Q8,U8,Y8,AC8,AG8,AK8,AO8,AS8,AW8) -> 0 | BB8: =SUM(F8,J8,N8,R8,V8,Z8,AD8,AH8,AL8,AP8,AT8,AX8) -> 0 | BC8: =SUM(G8,K8,O8,S8,W8,AA8,AE8,AI8,AM8,AQ8,AU8,AY8) -> 0
AZ9: =SUM(D9,H9,L9,P9,T9,X9,AB9,AF9,AJ9,AN9,AR9,AV9) -> 0 | BA9: =SUM(E9,I9,M9,Q9,U9,Y9,AC9,AG9,AK9,AO9,AS9,AW9) -> 0 | BB9: =SUM(F9,J9,N9,R9,V9,Z9,AD9,AH9,AL9,AP9,AT9,AX9) -> 0 | BC9: =SUM(G9,K9,O9,S9,W9,AA9,AE9,AI9,AM9,AQ9,AU9,AY9) -> 0
AZ10: =SUM(D10,H10,L10,P10,T10,X10,AB10,AF10,AJ10,AN10,AR10,AV10) -> 0 | BA10: =SUM(E10,I10,M10,Q10,U10,Y10,AC10,AG10,AK10,AO10,AS10,AW10) -> 0 | BB10: =SUM(F10,J10,N10,R10,V10,Z10,AD10,AH10,AL10,AP10,AT10,AX10) -> 0 | BC10: =SUM(G10,K10,O10,S10,W10,AA10,AE10,AI10,AM10,AQ10,AU10,AY10) -> 0
A11: output 3 | AZ11: =SUM(D11,H11,L11,P11,T11,X11,AB11,AF11,AJ11,AN11,AR11,AV11) -> 0 | BA11: =SUM(E11,I11,M11,Q11,U11,Y11,AC11,AG11,AK11,AO11,AS11,AW11) -> 0 | BB11: =SUM(F11,J11,N11,R11,V11,Z11,AD11,AH11,AL11,AP11,AT11,AX11) -> 0 | BC11: =SUM(G11,K11,O11,S11,W11,AA11,AE11,AI11,AM11,AQ11,AU11,AY11) -> 0
AZ12: =SUM(D12,H12,L12,P12,T12,X12,AB12,AF12,AJ12,AN12,AR12,AV12) -> 0 | BA12: =SUM(E12,I12,M12,Q12,U12,Y12,AC12,AG12,AK12,AO12,AS12,AW12) -> 0 | BB12: =SUM(F12,J12,N12,R12,V12,Z12,AD12,AH12,AL12,AP12,AT12,AX12) -> 0 | BC12: =SUM(G12,K12,O12,S12,W12,AA12,AE12,AI12,AM12,AQ12,AU12,AY12) -> 0
AZ13: =SUM(D13,H13,L13,P13,T13,X13,AB13,AF13,AJ13,AN13,AR13,AV13) -> 0 | BA13: =SUM(E13,I13,M13,Q13,U13,Y13,AC13,AG13,AK13,AO13,AS13,AW13) -> 0 | BB13: =SUM(F13,J13,N13,R13,V13,Z13,AD13,AH13,AL13,AP13,AT13,AX13) -> 0 | BC13: =SUM(G13,K13,O13,S13,W13,AA13,AE13,AI13,AM13,AQ13,AU13,AY13) -> 0
AZ14: =SUM(D14,H14,L14,P14,T14,X14,AB14,AF14,AJ14,AN14,AR14,AV14) -> 0 | BA14: =SUM(E14,I14,M14,Q14,U14,Y14,AC14,AG14,AK14,AO14,AS14,AW14) -> 0 | BB14: =SUM(F14,J14,N14,R14,V14,Z14,AD14,AH14,AL14,AP14,AT14,AX14) -> 0 | BC14: =SUM(G14,K14,O14,S14,W14,AA14,AE14,AI14,AM14,AQ14,AU14,AY14) -> 0
AZ15: =SUM(D15,H15,L15,P15,T15,X15,AB15,AF15,AJ15,AN15,AR15,AV15) -> 0 | BA15: =SUM(E15,I15,M15,Q15,U15,Y15,AC15,AG15,AK15,AO15,AS15,AW15) -> 0 | BB15: =SUM(F15,J15,N15,R15,V15,Z15,AD15,AH15,AL15,AP15,AT15,AX15) -> 0 | BC15: =SUM(G15,K15,O15,S15,W15,AA15,AE15,AI15,AM15,AQ15,AU15,AY15) -> 0
AZ16: =SUM(D16,H16,L16,P16,T16,X16,AB16,AF16,AJ16,AN16,AR16,AV16) -> 0 | BA16: =SUM(E16,I16,M16,Q16,U16,Y16,AC16,AG16,AK16,AO16,AS16,AW16) -> 0 | BB16: =SUM(F16,J16,N16,R16,V16,Z16,AD16,AH16,AL16,AP16,AT16,AX16) -> 0 | BC16: =SUM(G16,K16,O16,S16,W16,AA16,AE16,AI16,AM16,AQ16,AU16,AY16) -> 0

Sheet Outcome indicators
A1: Level | B1: Indicators | C1: Q1 | K1: Q2 | S1: Q3 | AA1: Q4 | AI1: Actual
C2: Numerator | G2: Denominator | K2: Numerator | O2: Denominator | S2: Numerator | W2: Denominator | AA2: Numerator | AE2: Denominator | AI2: % M | AJ2: % FM | AK2: % M (CWDs) | AL2: % FM (CWDs)
C3: N-M | D3: N-FM | E3: N-M (CWDs) | F3: N-FM (CWDs) | G3: D-M | H3: D-FM | I3: D-M (CWDs) | J3: D-FM (CWDs) | K3: N-M | L3: N-FM | M3: N-M (CWDs) | N3: N-FM (CWDs) | O3: D-M | P3: D-FM | Q3: D-M (CWDs) | R3: D-FM (CWDs) | S3: N-M | T3: N-FM | U3: N-M (CWDs) | V3: N-FM (CWDs) | W3: D-M | X3: D-FM | Y3: D-M (CWDs) | Z3: D-FM (CWDs) | AA3: N-M | AB3: N-FM | AC3: N-M (CWDs) | AD3: N-FM (CWDs) | AE3: D-M | AF3: D-FM | AG3: D-M (CWDs) | AH3: D-FM (CWDs)
A4: Overall Objective | AI4: =SUM(C4,K4,S4,AA4)/SUM(G4,O4,W4,AE4) -> #DIV/0! | AJ4: =SUM(D4,L4,T4,AB4)/SUM(H4,P4,X4,AF4) -> #DIV/0! | AK4: =SUM(E4,M4,U4,AC4)/SUM(I4,Q4,Y4,AG4) -> #DIV/0! | AL4: =SUM(F4,N4,V4,AD4)/SUM(J4,R4,Z4,AH4) -> #DIV/0!
AI5: =SUM(C5,K5,S5,AA5)/SUM(G5,O5,W5,AE5) -> #DIV/0! | AJ5: =SUM(D5,L5,T5,AB5)/SUM(H5,P5,X5,AF5) -> #DIV/0! | AK5: =SUM(E5,M5,U5,AC5)/SUM(I5,Q5,Y5,AG5) -> #DIV/0! | AL5: =SUM(F5,N5,V5,AD5)/SUM(J5,R5,Z5,AH5) -> #DIV/0!
A6: Outcome | AI6: =SUM(C6,K6,S6,AA6) -> 0
AI7: =SUM(C7,K7,S7,AA7)/SUM(G7,O7,W7,AE7) -> #DIV/0! | AJ7: =SUM(D7,L7,T7,AB7)/SUM(H7,P7,X7,AF7) -> #DIV/0! | AK7: =SUM(E7,M7,U7,AC7)/SUM(I7,Q7,Y7,AG7) -> #DIV/0! | AL7: =SUM(F7,N7,V7,AD7)/SUM(J7,R7,Z7,AH7) -> #DIV/0!
AI8: =SUM(C8,K8,S8,AA8)/SUM(G8,O8,W8,AE8) -> #DIV/0! | AJ8: =SUM(D8,L8,T8,AB8)/SUM(H8,P8,X8,AF8) -> #DIV/0! | AK8: =SUM(E8,M8,U8,AC8)/SUM(I8,Q8,Y8,AG8) -> #DIV/0! | AL8: =SUM(F8,N8,V8,AD8)/SUM(J8,R8,Z8,AH8) -> #DIV/0!
AI9: =SUM(C9,K9,S9,AA9)/SUM(G9,O9,W9,AE9) -> #DIV/0! | AJ9: =SUM(D9,L9,T9,AB9)/SUM(H9,P9,X9,AF9) -> #DIV/0! | AK9: =SUM(E9,M9,U9,AC9)/SUM(I9,Q9,Y9,AG9) -> #DIV/0! | AL9: =SUM(F9,N9,V9,AD9)/SUM(J9,R9,Z9,AH9) -> #DIV/0!
AI10: =SUM(C10,K10,S10,AA10)/SUM(G10,O10,W10,AE10) -> #DIV/0! | AJ10: =SUM(D10,L10,T10,AB10)/SUM(H10,P10,X10,AF10) -> #DIV/0! | AK10: =SUM(E10,M10,U10,AC10)/SUM(I10,Q10,Y10,AG10) -> #DIV/0! | AL10: =SUM(F10,N10,V10,AD10)/SUM(J10,R10,Z10,AH10) -> #DIV/0!
AI11: =SUM(C11,K11,S11,AA11)/SUM(G11,O11,W11,AE11) -> #DIV/0! | AJ11: =SUM(D11,L11,T11,AB11)/SUM(H11,P11,X11,AF11) -> #DIV/0! | AK11: =SUM(E11,M11,U11,AC11)/SUM(I11,Q11,Y11,AG11) -> #DIV/0! | AL11: =SUM(F11,N11,V11,AD11)/SUM(J11,R11,Z11,AH11) -> #DIV/0!
AI12: =SUM(C12,K12,S12,AA12)/SUM(G12,O12,W12,AE12) -> #DIV/0! | AJ12: =SUM(D12,L12,T12,AB12)/SUM(H12,P12,X12,AF12) -> #DIV/0! | AK12: =SUM(E12,M12,U12,AC12)/SUM(I12,Q12,Y12,AG12) -> #DIV/0! | AL12: =SUM(F12,N12,V12,AD12)/SUM(J12,R12,Z12,AH12) -> #DIV/0!

Sheet Beneficiaries Breakdown
B1: 1. Beneficiaries Dashboard | K1: Date Q1
K2: Date Q2 | O2: Legend | P2: Abbreviation
B3: Project Beneficiaries | K3: Date Q3 | O3: Nb | P3: Number of beneficiaries
B4: Direct BNFs | C4: =SUM(D7:E7) -> 550 | K4: Date Q4 | O4: BNF | P4: beneficiaries
B5: In Direct BNF | O5: PWC | P5: People with disability
B6: Total | C6: Sex / Age | D6: Female | E6: Male | F6: CWDs Male | G6: CWDs Female | H6: Children | I6: Youth | J6: Parents | K6: Local Educator | L6: NAWA educator | O6: Ax | P6: Activity
C7: Nb of beneficiaries | D7: =SUM(D12,D17,D22,D27) -> 125 | E7: =SUM(E12,E17,E22,E27) -> 425 | F7: =SUM(F12,F17,F22,F27) -> 5 | G7: =SUM(G12,G17,G22,G27) -> 3 | H7: =SUM(H12,H17,H22,H27) -> 163 | I7: =SUM(I12,I17,I22,I27) -> 378 | J7: =SUM(J12,J17,J22,J27) -> 398 | K7: =SUM(K12,K17,K22,K27) -> 61 | L7: =SUM(L12,L17,L22,L27) -> 4 | O7: Qx | P7: Quarter
C8: CWDS | D8: =SUM(F7:G7)/C4 -> 0.014545455 | F8: =F7/SUM(E43:F44,L43:M44,E60:F61,L60:M61,E77:F78,L77:M78,E94:F95,L94:M95) -> 0.2 | G8: =G7/SUM(E51:F52,L51:M52,E68:F69,L68:M69,E85:F86,L85:M86,E102:F103,L102:M103) -> 0.375
C9: PWDs
O10: User Instructions Beneficiaries dashboard is automatic calcution DO NOT change formulas except for MEAL staff Database 2 data entry should be done by project team, MEAL to follow up and ensure accuracy and consistency with MoVs (only UNIQUE BNFs no double counting) Data update should be done on Quarterly basis basis (unless no changes occured on BN numbers) Direct BNFs are those who participate directly in the project, and thus benefit from its existence i.e teachers who attended trainings with Nawa Non-Direct BNFs are those stakeholders who might benefit from direct interaction with Nawa beneficiaires or all those living within the zone of influence of the project (not always the case) i.e teachers (who didn't join the training) but possible interaction with their colleagues who did joined the trainings
B11: Q1 | C11: Sex / Age | D11: Female | E11: Male | F11: CWDs Male | G11: CWDs Female | H11: Children | I11: Youth | J11: Parents | K11: Local Educator | L11: NAWA educator
C12: Nb of beneficiaries | D12: =S56 -> 40 | E12: =S48 -> 350 | F12: =SUM(T43:T44) -> 0 | G12: =SUM(T51:T52) -> 3 | H12: =SUM(S43:T44,S51:T52) -> 73 | I12: =SUM(H48:I48,O48:P48,H56:I56,O56:P56) -> 335 | J12: =SUM(S45:T45,S53:T53) -> 335 | K12: =SUM(S46:T46,S54:T54) -> 15 | L12: =SUM(S47:T47,S55:T55) -> 0
C13: CWDS | D13: =SUM(F12:G12)/C9 -> #VALUE!
C14: PWDs | D14: =SUM(O56:R56) -> 15 | E14: =SUM(O48:R48) -> 0
B16: Q2 | C16: Sex / Age | D16: Female | E16: Male | F16: CWDs Male | G16: CWDs Female | H16: Children | I16: Youth | J16: Parents | K16: Local Educator | L16: NAWA educator
C17: Nb of beneficiaries | D17: =S73 -> 50 | E17: =S65 -> 15 | F17: =SUM(T60:T61) -> 0 | G17: =SUM(T68:T69) -> 0 | H17: =SUM(S60:T61,S68:T69) -> 65 | I17: =SUM(G65:H65,O65:P65,G73:H73,O73:P73) -> 15 | J17: =SUM(S62:T62,S70:T70) -> 25 | K17: =SUM(S63:T63,S71:T71) -> 0 | L17: =SUM(S64:T64,S72:T72) -> 0
C18: CWDS | D18: =SUM(F17:G17)/C13 -> #VALUE!
C19: PWDs | D19: =SUM(O73:R73) -> 5 | E19: =SUM(O65:R65) -> 0
B21: Q3 | C21: Sex / Age | D21: Female | E21: Male | F21: CWDs Male | G21: CWDs Female | H21: Children | I21: Youth | J21: Parents | K21: Local Educator | L21: NAWA educator
C22: Nb of beneficiaries | D22: =S90 -> 15 | E22: =S82 -> 20 | F22: =SUM(T77:T78) -> 5 | G22: =SUM(T85:T86) -> 0 | H22: =SUM(S77:T78,S85:T86) -> 25 | I22: =SUM(G82:H82,O82:P82,G90:H90,O90:P90) -> 3 | J22: =SUM(S79:T79,S87:T87) -> 18 | K22: =SUM(S80:T80,S88:T88) -> 3 | L22: =SUM(S81:T81,S89:T89) -> 2
C23: CWDS | D23: =SUM(F22:G22)/C18 -> #VALUE!
C24: PWDs | D24: =SUM(O90:R90) -> 3 | E24: =SUM(O82:R82) -> 2
B26: Q4 | C26: Sex / Age | D26: Female | E26: Male | F26: CWDs Male | G26: CWDs Female | H26: Children | I26: Youth | J26: Parents | K26: Local Educator | L26: NAWA educator
C27: Nb of beneficiaries | D27: =S107 -> 20 | E27: =S99 -> 40 | F27: =SUM(T94:T95) -> 0 | G27: =SUM(T102:T103) -> 0 | H27: =SUM(S94:T95,S102:T103) -> 0 | I27: =SUM(H99:I99,O99:P99,H107:I107,O107:P107) -> 25 | J27: =SUM(S96:T96,S104:T104) -> 20 | K27: =SUM(S97:T97,S105:T105) -> 43 | L27: =SUM(S98:T98,S106:T106) -> 2
C28: CWDS | D28: =SUM(F27:G27)/C23 -> #VALUE!
C29: PWDs | D29: =SUM(O107:R107) -> 2 | E29: =SUM(O99:R99) -> 3
B31: Activities | C31: R1 | D31: R2 | E31: R3
B32: Nb of beneficiaries | C32: {=SUMPRODUCT(($B$43:$B$47=C31)*($S$43:$T$47)+($B$51:$B$55=C31)*($S$51:$T$55)+($B$68:$B$72=C31)*($S$68:$T$72)+($B$60:$B$64=C31)*($S$60:$T$64)+($B$77:$B$81=$E$31)*($S$77:$T$81)+($B$85:$B$89=C31)*($S$85:$T$89)+($B$94:$B$98=C31)*($S$94:$T$98)+($B$102:$B$106=C31)*($S$102:$T$106))} -> 8 | D32: {=SUMPRODUCT(($B$43:$B$47=D31)*($S$43:$T$47)+($B$51:$B$55=D31)*($S$51:$T$55)+($B$68:$B$72=D31)*($S$68:$T$72)+($B$60:$B$64=D31)*($S$60:$T$64)+($B$77:$B$81=$E$31)*($S$77:$T$81)+($B$85:$B$89=D31)*($S$85:$T$89)+($B$94:$B$98=D31)*($S$94:$T$98)+($B$102:$B$106=D31)*($S$102:$T$106))} -> 15 | E32: {=SUMPRODUCT(($B$43:$B$47=E31)*($S$43:$T$47)+($B$51:$B$55=E31)*($S$51:$T$55)+($B$68:$B$72=E31)*($S$68:$T$72)+($B$60:$B$64=E31)*($S$60:$T$64)+($B$77:$B$81=$E$31)*($S$77:$T$81)+($B$85:$B$89=E31)*($S$85:$T$89)+($B$94:$B$98=E31)*($S$94:$T$98)+($B$102:$B$106=E31)*($S$102:$T$106))} -> 355
B34: Activity type | C34: Al Khidr library interventions | D34: Schools interventions | E34: Parents activities | F34: Local educator trainings | G34: NAWA educator training
B35: Nb of beneficiaries | C35: {=SUMPRODUCT(($C$43:$C$47=C34)*($S$43:$T$47)+($C$51:$C$55=C34)*($S$51:$T$55)+($C$68:$C$72=C34)*($S$68:$T$72)+($C$60:$C$64=C34)*($S$60:$T$64)+($C$77:$C$81=$E$31)*($S$77:$T$81)+($C$85:$C$89=C34)*($S$85:$T$89)+($C$94:$C$98=C34)*($S$94:$T$98)+($C$102:$C$106=C34)*($S$102:$T$106))} -> 8 | D35: {=SUMPRODUCT(($C$43:$C$47=D34)*($S$43:$T$47)+($C$51:$C$55=D34)*($S$51:$T$55)+($C$68:$C$72=D34)*($S$68:$T$72)+($C$60:$C$64=D34)*($S$60:$T$64)+($C$77:$C$81=$E$31)*($S$77:$T$81)+($C$85:$C$89=D34)*($S$85:$T$89)+($C$94:$C$98=D34)*($S$94:$T$98)+($C$102:$C$106=D34)*($S$102:$T$106))} -> 130 | E35: {=SUMPRODUCT(($C$43:$C$47=E34)*($S$43:$T$47)+($C$51:$C$55=E34)*($S$51:$T$55)+($C$68:$C$72=E34)*($S$68:$T$72)+($C$60:$C$64=E34)*($S$60:$T$64)+($C$77:$C$81=$E$31)*($S$77:$T$81)+($C$85:$C$89=E34)*($S$85:$T$89)+($C$94:$C$98=E34)*($S$94:$T$98)+($C$102:$C$106=E34)*($S$102:$T$106))} -> 398 | F35: {=SUMPRODUCT(($C$43:$C$47=F34)*($S$43:$T$47)+($C$51:$C$55=F34)*($S$51:$T$55)+($C$68:$C$72=F34)*($S$68:$T$72)+($C$60:$C$64=F34)*($S$60:$T$64)+($C$77:$C$81=$E$31)*($S$77:$T$81)+($C$85:$C$89=F34)*($S$85:$T$89)+($C$94:$C$98=F34)*($S$94:$T$98)+($C$102:$C$106=F34)*($S$102:$T$106))} -> 61 | G35: {=SUMPRODUCT(($C$43:$C$47=G34)*($S$43:$T$47)+($C$51:$C$55=G34)*($S$51:$T$55)+($C$68:$C$72=G34)*($S$68:$T$72)+($C$60:$C$64=G34)*($S$60:$T$64)+($C$77:$C$81=$E$31)*($S$77:$T$81)+($C$85:$C$89=G34)*($S$85:$T$89)+($C$94:$C$98=G34)*($S$94:$T$98)+($C$102:$C$106=G34)*($S$102:$T$106))} -> 2
B39: 2. Database - only for direct beneficiaries
B41: Q1 Males | E41: Males | L41: Males(CWDs) | S41: Total
B42: RESULT | C42: Activity | D42: Target | E42: 4-6 years | F42: 7 - 10 years | G42: 11- 15 years | H42: 16-18 years | I42: 19- 25 years | J42: 26-40 years | K42: >=41 years | L42: 4-6 years | M42: 7 - 10 years | N42: 11- 15 years | O42: 16-18 years | P42: 19- 25 years | Q42: 26-40 years | R42: >=41 years | S42: Male | T42: Males (CWDs)
B43: R1 | C43: Al Khidr library interventions | D43: Children | S43: =SUM(E43:K43) -> 0 | T43: =SUM(L43:R43) -> 0
C44: Schools interventions | D44: low academic achiever children | G44: 50 | S44: =SUM(E44:K44) -> 50 | T44: =SUM(L44:R44) -> 0
B45: R3 | C45: Parents activities | D45: Parents | H45: 100 | I45: 200 | S45: =SUM(E45:K45) -> 300 | T45: =SUM(L45:R45) -> 0
C46: Local educator trainings | D46: Local Educator | S46: =SUM(E46:K46) -> 0 | T46: =SUM(L46:R46) -> 0
C47: NAWA educator training | D47: NAWA educators | S47: =SUM(E47:K47) -> 0 | T47: =SUM(L47:R47) -> 0
B48: Total Q1 | E48: =SUM(E43:E47) -> 0 | F48: =SUM(F43:F47) -> 0 | G48: =SUM(G43:G47) -> 50 | H48: =SUM(H43:H47) -> 100 | I48: =SUM(I43:I47) -> 200 | J48: =SUM(J43:J47) -> 0 | K48: =SUM(K43:K47) -> 0 | L48: =SUM(L43:L47) -> 0 | ... T48: =SUM(T43:T47) -> 0
B49: Q1 Females | E49: Females | L49: Females (CWDs) | S49: Total
...

Sheet MEAL Calendar
A1: No. | B1: Activity | C1: target | D1: Responsibility | E1: Frequency | F1: Achievement Level (%) | G1: planned/Actual | H1: 43922 | L1: 43952 | P1: 43983 | T1: 44013 | X1: 44044 | AB1: 44075 | AF1: 44105 | AJ1: 44136 | AN1: 44166 | AR1: 44197 | AV1: 44228 | AZ1: 44256 | BD1: Brief Updates | BE1: As planned
H2: WK1 | I2: WK2 | J2: WK3 | K2: WK4 | L2: WK1 | M2: WK2 | N2: WK3 | O2: WK4 | P2: WK1 | Q2: WK2 | R2: WK3 | S2: WK4 | T2: WK1 | U2: WK2 | V2: WK3 | W2: WK4 | X2: WK1 | Y2: WK2 | Z2: WK3 | AA2: WK4 | AB2: WK1 | AC2: WK2 | AD2: WK3 | AE2: WK4 | AF2: WK1 | AG2: WK2 | AH2: WK3 | AI2: WK4 | AJ2: WK1 | AK2: WK2 | AL2: WK3 | AM2: WK4 | AN2: WK1 | AO2: WK2 | AP2: WK3 | AQ2: WK4 | AR2: WK1 | AS2: WK2 | AT2: WK3 | AU2: WK4 | AV2: WK1 | AW2: WK2 | AX2: WK3 | AY2: WK4 | AZ2: WK1 | BA2: WK2 | BB2: WK3 | BC2: WK4 | BE2: Delayed activity
A3: 1 | B3: Monitoring and Evaluation | F3: =AVERAGE(F5,F13,F25,F37,F49,F61) -> #DIV/0! | G3: Planned | H3: =SUM(H5,H7,H9,H11) -> 0 | I3: =SUM(I5,I7,I9,I11) -> 0 | J3: =SUM(J5,J7,J9,J11) -> 0 | K3: =SUM(K5,K7,K9,K11) -> 0 | L3: =SUM(L5,L7,L9,L11) -> 0 | M3: =SUM(M5,M7,M9,M11) -> 0 | N3: =SUM(N5,N7,N9,N11) -> 0 | O3: =SUM(O5,O7,O9,O11) -> 0 | ... S3: =SUM(S5,S7,S9,S11) -> 0 | U3: =SUM(U5,U7,U9,U11) -> 0 | V3: =SUM(V5,V7,V9,V11) -> 0 | W3: =SUM(W5,W7,W9,W11) -> 0 | X3: =SUM(X5,X7,X9,X11) -> 0 | Y3: =SUM(Y5,Y7,Y9,Y11) -> 0 | Z3: =SUM(Z5,Z7,Z9,Z11) -> 0 | AA3: =SUM(AA5,AA7,AA9,AA11) -> 0 | AB3: =SUM(AB5,AB7,AB9,AB11) -> 0 | ... BC3: =SUM(BC5,BC7,BC9,BC11) -> 0
G4: Actual | H4: =SUM(H6,H8,H10,H12) -> 0 | I4: =SUM(I6,I8,I10,I12) -> 0 | J4: =SUM(J6,J8,J10,J12) -> 0 | K4: =SUM(K6,K8,K10,K12) -> 0 | L4: =SUM(L6,L8,L10,L12) -> 0 | M4: =SUM(M6,M8,M10,M12) -> 0 | N4: =SUM(N6,N8,N10,N12) -> 0 | O4: =SUM(O6,O8,O10,O12) -> 0 | ... S4: =SUM(S6,S8,S10,S12) -> 0 | U4: =SUM(U6,U8,U10,U12) -> 0 | V4: =SUM(V6,V8,V10,V12) -> 0 | W4: =SUM(W6,W8,W10,W12) -> 0 | X4: =SUM(X6,X8,X10,X12) -> 0 | Y4: =SUM(Y6,Y8,Y10,Y12) -> 0 | Z4: =SUM(Z6,Z8,Z10,Z12) -> 0 | AA4: =SUM(AA6,AA8,AA10,AA12) -> 0 | AB4: =SUM(AB6,AB8,AB10,AB12) -> 0 | ... BC4: =SUM(BC6,BC8,BC10,BC12) -> 0
A5: 1.1 | B5: Monitoring visits | C5: 5 | F5: =SUM(H6:BC6)/SUM(H5:BC5) -> #DIV/0! | G5: Planned | H5: =H7+H9+H11 -> 0 | I5: =I7+I9+I11 -> 0 | J5: =J7+J9+J11 -> 0 | K5: =K7+K9+K11 -> 0 | L5: =L7+L9+L11 -> 0 | M5: =M7+M9+M11 -> 0 | N5: =N7+N9+N11 -> 0 | O5: =O7+O9+O11 -> 0 | ... S5: =S7+S9+S11 -> 0 | T5: =T9+T11+T13 -> 0 | U5: =U7+U9+U11 -> 0 | V5: =V7+V9+V11 -> 0 | W5: =W7+W9+W11 -> 0 | X5: =X7+X9+X11 -> 0 | Y5: =Y7+Y9+Y11 -> 0 | Z5: =Z7+Z9+Z11 -> 0 | AA5: =AA7+AA9+AA11 -> 0 | AB5: =AB7+AB9+AB11 -> 0 | ... BC5: =BC7+BC9+BC11 -> 0
G6: Actual | H6: =H8+H10+H12 -> 0 | I6: =I8+I10+I12 -> 0 | J6: =J8+J10+J12 -> 0 | K6: =K8+K10+K12 -> 0 | L6: =L8+L10+L12 -> 0 | M6: =M8+M10+M12 -> 0 | N6: =N8+N10+N12 -> 0 | O6: =O8+O10+O12 -> 0 | ... S6: =S8+S10+S12 -> 0 | T6: =T10+T12+T14 -> 0 | U6: =U8+U10+U12 -> 0 | V6: =V8+V10+V12 -> 0 | W6: =W8+W10+W12 -> 0 | X6: =X8+X10+X12 -> 0 | Y6: =Y8+Y10+Y12 -> 0 | Z6: =Z8+Z10+Z12 -> 0 | AA6: =AA8+AA10+AA12 -> 0 | AB6: =AB8+AB10+AB12 -> 0 | ... BC6: =BC8+BC10+BC12 -> 0
B7: Data collection | C7: 5 | D7: MEAL department | E7: monthly | F7: =SUM(H8:BC8)/SUM(H7:BC7) -> #DIV/0! | G7: Planned
G8: Actual
B9: Draft report | C9: 5 | D9: MEAL department | E9: monthly | F9: =SUM(H10:BC10)/SUM(H9:BC9) -> #DIV/0! | G9: Planned
G10: Actual
B11: Final report | C11: 4 | D11: MEAL Officer | E11: monthly | F11: =SUM(H12:BC12)/SUM(H11:BC11) -> #DIV/0! | G11: Planned
G12: Actual
A13: 1.2 | B13: Baseline | C13: 2 | D13: MEAL Department | E13: Once a year for new beneficiaries | F13: =SUM(H14:BC14)/SUM(H13:BC13) -> 0 | G13: Planned | H13: 0 | I13: =SUM(I15,I17,I19,I21,I23) -> 0 | J13: =SUM(J15,J17,J19,J21,J23) -> 0 | K13: =SUM(K15,K17,K19,K21,K23) -> 0 | L13: =SUM(L15,L17,L19,L21,L23) -> 0 | M13: =SUM(M15,M17,M19,M21,M23) -> 0 | N13: =SUM(N15,N17,N19,N21,N23) -> 0 | O13: =SUM(O15,O17,O19,O21,O23) -> 0 | P13: =SUM(P15,P17,P19,P21,P23) -> 0 | ... AB13: =SUM(AB15,AB17,AB19,AB21,AB23) -> 0 | AC13: 0 | AD13: 1 | AE13: =SUM(AE15,AE17,AE19,AE21,AE23) -> 0 | AF13: =SUM(AF15,AF17,AF19,AF21,AF23) -> 0 | AG13: =SUM(AG15,AG17,AG19,AG21,AG23) -> 0 | AH13: =SUM(AH15,AH17,AH19,AH21,AH23) -> 0 | AI13: =SUM(AI15,AI17,AI19,AI21,AI23) -> 0 | AJ13: =SUM(AJ15,AJ17,AJ19,AJ21,AJ23) -> 0 | AK13: =SUM(AK15,AK17,AK19,AK21,AK23) -> 0 | AL13: =SUM(AL15,AL17,AL19,AL21,AL23) -> 0 | ... BC13: =SUM(BC15,BC17,BC19,BC21,BC23) -> 0
G14: Actual | H14: =SUM(H16,H18,H20,H22,H24) -> 0 | I14: =SUM(I16,I18,I20,I22,I24) -> 0 | J14: =SUM(J16,J18,J20,J22,J24) -> 0 | K14: =SUM(K16,K18,K20,K22,K24) -> 0 | L14: =SUM(L16,L18,L20,L22,L24) -> 0 | M14: =SUM(M16,M18,M20,M22,M24) -> 0 | N14: =SUM(N16,N18,N20,N22,N24) -> 0 | O14: =SUM(O16,O18,O20,O22,O24) -> 0 | ... AB14: =SUM(AB16,AB18,AB20,AB22,AB24) -> 0 | AC14: 0 | AD14: 0 | AE14: =SUM(AE16,AE18,AE20,AE22,AE24) -> 0 | AF14: =SUM(AF16,AF18,AF20,AF22,AF24) -> 0 | AG14: =SUM(AG16,AG18,AG20,AG22,AG24) -> 0 | AH14: =SUM(AH16,AH18,AH20,AH22,AH24) -> 0 | AI14: =SUM(AI16,AI18,AI20,AI22,AI24) -> 0 | AJ14: =SUM(AJ16,AJ18,AJ20,AJ22,AJ24) -> 0 | AK14: =SUM(AK16,AK18,AK20,AK22,AK24) -> 0 | AL14: =SUM(AL16,AL18,AL20,AL22,AL24) -> 0 | ... BC14: =SUM(BC16,BC18,BC20,BC22,BC24) -> 0
B15: 1.3.1. Development of the tools | C15: 1 | D15: MEAL Officer | F15: =SUM(H16:BC16)/SUM(H15:BC15) -> #DIV/0! | G15: Planned
G16: Actual
B17: 1.3.2. Data collection | C17: 2 | D17: Project staff | F17: =SUM(H18:BC18)/SUM(H17:BC17) -> #DIV/0! | G17: Planned
G18: Actual
B19: 1.3.3. Data entry/cleaning | C19: 2 | D19: MEAL department | F19: =SUM(H20:BC20)/SUM(H19:BC19) -> #DIV/0! | G19: Planned
G20: Actual
B21: 1.3.4. Data analysis | C21: 2 | D21: MEAL department | F21: =SUM(H22:BC22)/SUM(H21:BC21) -> #DIV/0! | G21: Planned
G22: Actual
B23: 1.3.5. Reporting | C23: 1 | D23: MEAL Officer | F23: =SUM(H24:BC24)/SUM(H23:BC23) -> #DIV/0! | G23: Planned
G24: Actual
A25: 1.3 | B25: Endine | D25: MEAL Department | E25: Once a year for exit beneficiaries | F25: =SUM(H26:BC26)/SUM(H25:BC25) -> 0 | G25: Planned | H25: 0 | I25: =SUM(I27,I29,I31,I33,I35) -> 0 | J25: =SUM(J27,J29,J31,J33,J35) -> 0 | K25: =SUM(K27,K29,K31,K33,K35) -> 0 | L25: =SUM(L27,L29,L31,L33,L35) -> 0 | M25: =SUM(M27,M29,M31,M33,M35) -> 0 | N25: =SUM(N27,N29,N31,N33,N35) -> 0 | O25: =SUM(O27,O29,O31,O33,O35) -> 0 | P25: =SUM(P27,P29,P31,P33,P35) -> 0 | ... S25: =SUM(S27,S29,S31,S33,S35) -> 0 | U25: =SUM(U27,U29,U31,U33,U35) -> 0 | V25: =SUM(V27,V29,V31,V33,V35) -> 0 | W25: =SUM(W27,W29,W31,W33,W35) -> 0 | X25: =SUM(X27,X29,X31,X33,X35) -> 0 | Y25: =SUM(Y27,Y29,Y31,Y33,Y35) -> 0 | Z25: =SUM(Z27,Z29,Z31,Z33,Z35) -> 0 | AA25: =SUM(AA27,AA29,AA31,AA33,AA35) -> 0 | AB25: =SUM(AB27,AB29,AB31,AB33,AB35) -> 0 | AD25: =SUM(AD27,AD29,AD31,AD33,AD35) -> 0 | AE25: =SUM(AE27,AE29,AE31,AE33,AE35) -> 0 | AF25: =SUM(AF27,AF29,AF31,AF33,AF35) -> 0 | AG25: =SUM(AG27,AG29,AG31,AG33,AG35) -> 0 | AH25: =SUM(AH27,AH29,AH31,AH33,AH35) -> 0 | AI25: =SUM(AI27,AI29,AI31,AI33,AI35) -> 0 | AJ25: =SUM(AJ27,AJ29,AJ31,AJ33,AJ35) -> 0 | AK25: =SUM(AK27,AK29,AK31,AK33,AK35) -> 0 | ... BC25: =SUM(BC27,BC29,BC31,BC33,BC35) -> 1
G26: Actual | H26: =SUM(H28,H30,H32,H34,H36) -> 0 | I26: =SUM(I28,I30,I32,I34,I36) -> 0 | J26: =SUM(J28,J30,J32,J34,J36) -> 0 | K26: =SUM(K28,K30,K32,K34,K36) -> 0 | L26: =SUM(L28,L30,L32,L34,L36) -> 0 | M26: =SUM(M28,M30,M32,M34,M36) -> 0 | N26: =SUM(N28,N30,N32,N34,N36) -> 0 | O26: =SUM(O28,O30,O32,O34,O36) -> 0 | ... S26: =SUM(S28,S30,S32,S34,S36) -> 0 | U26: =SUM(U28,U30,U32,U34,U36) -> 0 | V26: =SUM(V28,V30,V32,V34,V36) -> 0 | W26: =SUM(W28,W30,W32,W34,W36) -> 0 | X26: =SUM(X28,X30,X32,X34,X36) -> 0 | Y26: =SUM(Y28,Y30,Y32,Y34,Y36) -> 0 | Z26: =SUM(Z28,Z30,Z32,Z34,Z36) -> 0 | AA26: =SUM(AA28,AA30,AA32,AA34,AA36) -> 0 | AB26: =SUM(AB28,AB30,AB32,AB34,AB36) -> 0 | AD26: =SUM(AD28,AD30,AD32,AD34,AD36) -> 0 | AE26: =SUM(AE28,AE30,AE32,AE34,AE36) -> 0 | AF26: =SUM(AF28,AF30,AF32,AF34,AF36) -> 0 | AG26: =SUM(AG28,AG30,AG32,AG34,AG36) -> 0 | AH26: =SUM(AH28,AH30,AH32,AH34,AH36) -> 0 | AI26: =SUM(AI28,AI30,AI32,AI34,AI36) -> 0 | AJ26: =SUM(AJ28,AJ30,AJ32,AJ34,AJ36) -> 0 | AK26: =SUM(AK28,AK30,AK32,AK34,AK36) -> 0 | ... BC26: =SUM(BC28,BC30,BC32,BC34,BC36) -> 0
B27: 1.3.1. Development of the tools | D27: MEAL Officer | F27: =SUM(H28:BC28)/SUM(H27:BC27) -> 0 | G27: Planned | BC27: 1
G28: Actual
B29: 1.3.2. Data collection | D29: Project staff | F29: =SUM(H30:BC30)/SUM(H29:BC29) -> #DIV/0! | G29: Planned
G30: Actual
B31: 1.3.3. Data entry/cleaning | D31: MEAL department | F31: =SUM(H32:BC32)/SUM(H31:BC31) -> #DIV/0! | G31: Planned
G32: Actual
B33: 1.3.4. Data analysis | D33: MEAL department | F33: =SUM(H34:BC34)/SUM(H33:BC33) -> #DIV/0! | G33: Planned
G34: Actual
B35: 1.3.5. Reporting | D35: MEAL Officer | F35: =SUM(H36:BC36)/SUM(H35:BC35) -> #DIV/0! | G35: Planned
G36: Actual
A37: 2 | B37: Accountability: Feedback and Complaint Mechanism | D37: Not applicable yet | E37: Not applicable yet | F37: =SUM(H38:BC38)/SUM(H37:BC37) -> #DIV/0! | H37: =H39+H41+H43+H45 -> 0 | I37: =I39+I41+I43+I45 -> 0 | J37: =J39+J41+J43+J45 -> 0 | K37: =K39+K41+K43+K45 -> 0 | L37: =L39+L41+L43+L45 -> 0 | M37: =M39+M41+M43+M45 -> 0 | N37: =N39+N41+N43+N45 -> 0 | O37: =O39+O41+O43+O45 -> 0 | ... BC37: =BC39+BC41+BC43+BC45 -> 0
H38: =H40+H42+H44+H46 -> 0 | I38: =I40+I42+I44+I46 -> 0 | J38: =J40+J42+J44+J46 -> 0 | K38: =K40+K42+K44+K46 -> 0 | L38: =L40+L42+L44+L46 -> 0 | M38: =M40+M42+M44+M46 -> 0 | N38: =N40+N42+N44+N46 -> 0 | O38: =O40+O42+O44+O46 -> 0 | ... BC38: =BC40+BC42+BC44+BC46 -> 0
A39: 2.1 | B39: Developing the Joint feedback/complaint form and setting up Joint complaints and feedback mechanism | D39: Not applicable yet | F39: =SUM(H40:BC40)/SUM(H39:BC39) -> #DIV/0! | G39: Planned
G40: Actual
...

Sheet Assumptions Monitoring
A1: List of assumptions | B1: Mitigation Measures | C1: WAS THE ASSUMPTION FULFILLED? | D1: * IF "NO", OR "ONLY PARTLY", WHICH STRATEGY WAS ADOPTED BY THE PROJECT * IF "YES", NO COMMENT SHOULD BE PROVIDED

Sheet Learning Managment Process
A1: No. | B1: Result | C1: Activity | D1: Source of learning | E1: If "Other", please specify | F1: Recommendation/Learning | G1: Date (when the recommendation was added) | H1: Action | I1: Timing (deadline) | J1: Responsible | K1: Status | L1: Comments
A69: PDM
A70: Monitoring Visit
A71: FGD
A72: Lessons learned exercise
A73: Other
